Workbook

Sheet pack
A1: Meridian Pay, management pack
A2: month | B2: 2025-09
A3: materiality | B3: 25000
A5: line | B5: actual | C5: budget | D5: variance | E5: variance %
A6: Transaction fees | B6: =SUMIFS(calc!$D:$D,calc!$B:$B,$B$2,calc!$E:$E,$A6,calc!$F:$F,1) | C6: =SUMIFS(budget!$F:$F,budget!$A:$A,$B$2,budget!$D:$D,INDEX(map!$A$2:$A$12,MATCH($A6,map!$B$2:$B$12,0))) | D6: =IF(INDEX(map!$C$2:$C$12,MATCH($A6,map!$B$2:$B$12,0))="revenue",B6-C6,C6-B6) | E6: =IFERROR((B6-C6)/C6,"")
A7: Subscription fees | B7: =SUMIFS(calc!$D:$D,calc!$B:$B,$B$2,calc!$E:$E,$A7,calc!$F:$F,1) | C7: =SUMIFS(budget!$F:$F,budget!$A:$A,$B$2,budget!$D:$D,INDEX(map!$A$2:$A$12,MATCH($A7,map!$B$2:$B$12,0))) | D7: =IF(INDEX(map!$C$2:$C$12,MATCH($A7,map!$B$2:$B$12,0))="revenue",B7-C7,C7-B7) | E7: =IFERROR((B7-C7)/C7,"")
A8: FX markup | B8: =SUMIFS(calc!$D:$D,calc!$B:$B,$B$2,calc!$E:$E,$A8,calc!$F:$F,1) | C8: =SUMIFS(budget!$F:$F,budget!$A:$A,$B$2,budget!$D:$D,INDEX(map!$A$2:$A$12,MATCH($A8,map!$B$2:$B$12,0))) | D8: =IF(INDEX(map!$C$2:$C$12,MATCH($A8,map!$B$2:$B$12,0))="revenue",B8-C8,C8-B8) | E8: =IFERROR((B8-C8)/C8,"")
A9: Scheme and interchange | B9: =SUMIFS(calc!$D:$D,calc!$B:$B,$B$2,calc!$E:$E,$A9,calc!$F:$F,1) | C9: =SUMIFS(budget!$F:$F,budget!$A:$A,$B$2,budget!$D:$D,INDEX(map!$A$2:$A$12,MATCH($A9,map!$B$2:$B$12,0))) | D9: =IF(INDEX(map!$C$2:$C$12,MATCH($A9,map!$B$2:$B$12,0))="revenue",B9-C9,C9-B9) | E9: =IFERROR((B9-C9)/C9,"")
A10: Cloud hosting | B10: =SUMIFS(calc!$D:$D,calc!$B:$B,$B$2,calc!$E:$E,$A10,calc!$F:$F,1) | C10: =SUMIFS(budget!$F:$F,budget!$A:$A,$B$2,budget!$D:$D,INDEX(map!$A$2:$A$12,MATCH($A10,map!$B$2:$B$12,0))) | D10: =IF(INDEX(map!$C$2:$C$12,MATCH($A10,map!$B$2:$B$12,0))="revenue",B10-C10,C10-B10) | E10: =IFERROR((B10-C10)/C10,"")
A11: Salaries | B11: =SUMIFS(calc!$D:$D,calc!$B:$B,$B$2,calc!$E:$E,$A11,calc!$F:$F,1) | C11: =SUMIFS(budget!$F:$F,budget!$A:$A,$B$2,budget!$D:$D,INDEX(map!$A$2:$A$12,MATCH($A11,map!$B$2:$B$12,0))) | D11: =IF(INDEX(map!$C$2:$C$12,MATCH($A11,map!$B$2:$B$12,0))="revenue",B11-C11,C11-B11) | E11: =IFERROR((B11-C11)/C11,"")
A12: Marketing programmes | B12: =SUMIFS(calc!$D:$D,calc!$B:$B,$B$2,calc!$E:$E,$A12,calc!$F:$F,1) | C12: =SUMIFS(budget!$F:$F,budget!$A:$A,$B$2,budget!$D:$D,INDEX(map!$A$2:$A$12,MATCH($A12,map!$B$2:$B$12,0))) | D12: =IF(INDEX(map!$C$2:$C$12,MATCH($A12,map!$B$2:$B$12,0))="revenue",B12-C12,C12-B12) | E12: =IFERROR((B12-C12)/C12,"")
A13: Facilities and admin | B13: =SUMIFS(calc!$D:$D,calc!$B:$B,$B$2,calc!$E:$E,$A13,calc!$F:$F,1) | C13: =SUMIFS(budget!$F:$F,budget!$A:$A,$B$2,budget!$D:$D,INDEX(map!$A$2:$A$12,MATCH($A13,map!$B$2:$B$12,0))) | D13: =IF(INDEX(map!$C$2:$C$12,MATCH($A13,map!$B$2:$B$12,0))="revenue",B13-C13,C13-B13) | E13: =IFERROR((B13-C13)/C13,"")
A15: Revenue | B15: =B6+B7+B8 | C15: =C6+C7+C8 | D15: =B15-C15 | E15: =IFERROR((B15-C15)/C15,"")
A16: Cost of sales | B16: =B9+B10 | C16: =C9+C10 | D16: =C16-B16 | E16: =IFERROR((B16-C16)/C16,"")
A17: Gross profit | B17: =B15-B16 | C17: =C15-C16 | D17: =B17-C17 | E17: =IFERROR((B17-C17)/C17,"")
A18: Operating expenses | B18: =B11+B12+B13 | C18: =C11+C12+C13 | D18: =C18-B18 | E18: =IFERROR((B18-C18)/C18,"")
A19: EBITDA | B19: =B17-B18 | C19: =C17-C18 | D19: =B19-C19 | E19: =IFERROR((B19-C19)/C19,"")
A20: Gross margin | B20: =B17/B15 | C20: =C17/C15
A22: check: pack against ledger | B22: =ROUND((B15-B16-B18)-(SUMIFS(calc!$D:$D,calc!$B:$B,$B$2,calc!$F:$F,1,calc!$G:$G,"revenue")-SUMIFS(calc!$D:$D,calc!$B:$B,$B$2,calc!$F:$F,1,calc!$G:$G,"cogs")-SUMIFS(calc!$D:$D,calc!$B:$B,$B$2,calc!$F:$F,1,calc!$G:$G,"opex")),2) | C22: must be zero

Sheet actuals
A1: journal_id | B1: month | C1: cost_centre | D1: cost_centre_name | E1: account_code | F1: account_name | G1: line_type | H1: amount | I1: memo
A2: JE000001 | B2: 2024-01 | C2: CC900 | D2: Corporate | E2: 4000 | F2: Transaction fees | G2: revenue | H2: -1188222.14
A3: JE000002 | B3: 2024-01 | C3: CC900 | D3: Corporate | E3: 4100 | F3: Subscription fees | G3: revenue | H3: -486000.00
A4: JE000003 | B4: 2024-01 | C4: CC900 | D4: Corporate | E4: 4200 | F4: FX markup | G4: revenue | H4: -129065.51
A5: JE000004 | B5: 2024-01 | C5: CC900 | D5: Corporate | E5: 5000 | F5: Scheme and interchange costs | G5: cogs | H5: 676057.43
A6: JE000005 | B6: 2024-01 | C6: CC900 | D6: Corporate | E6: 5100 | F6: Cloud hosting | G6: cogs | H6: 85000.00
A7: JE000006 | B7: 2024-01 | C7: CC100 | D7: Engineering | E7: 6000 | F7: Salaries and wages | G7: opex | H7: 448400.00
A8: JE000007 | B8: 2024-01 | C8: CC200 | D8: Sales | E8: 6000 | F8: Salaries and wages | G8: opex | H8: 131600.00
A9: JE000008 | B9: 2024-01 | C9: CC300 | D9: Marketing | E9: 6000 | F9: Salaries and wages | G9: opex | H9: 53400.00
A10: JE000009 | B10: 2024-01 | C10: CC400 | D10: Customer support | E10: 6000 | F10: Salaries and wages | G10: opex | H10: 106400.00
A11: JE000010 | B11: 2024-01 | C11: CC500 | D11: General and administrative | E11: 6000 | F11: Salaries and wages | G11: opex | H11: 100100.00
A12: JE000011 | B12: 2024-01 | C12: CC300 | D12: Marketing | E12: 6100 | F12: Marketing programmes | G12: opex | H12: 180000.00
A13: JE000012 | B13: 2024-01 | C13: CC500 | D13: General and administrative | E13: 6200 | F13: Facilities and administration | G13: opex | H13: 148000.00
... A277: JE000275 | B277: 2025-07 | C277: CC900 | D277: Corporate | E277: 5100 | F277: Cloud hosting | G277: cogs | H277: 29186.86
A278: JE000276 | B278: 2025-07 | C278: CC500 | D278: General and administrative | E278: 6200 | F278: Facilities and administration | G278: opex | H278: 88000.00 | I278: cloud invoice, coded in error
A279: JE000277 | B279: 2025-07 | C279: CC100 | D279: Engineering | E279: 6000 | F279: Salaries and wages | G279: opex | H279: 590000.00
A280: JE000278 | B280: 2025-07 | C280: CC200 | D280: Sales | E280: 6000 | F280: Salaries and wages | G280: opex | H280: 188000.00
A281: JE000279 | B281: 2025-07 | C281: CC300 | D281: Marketing | E281: 6000 | F281: Salaries and wages | G281: opex | H281: 71200.00
A282: JE000280 | B282: 2025-07 | C282: CC400 | D282: Customer support | E282: 6000 | F282: Salaries and wages | G282: opex | H282: 123200.00
A283: JE000281 | B283: 2025-07 | C283: CC500 | D283: General and administrative | E283: 6000 | F283: Salaries and wages | G283: opex | H283: 118300.00
A284: JE000282 | B284: 2025-07 | C284: CC300 | D284: Marketing | E284: 6100 | F284: Marketing programmes | G284: opex | H284: 180000.00
A285: JE000283 | B285: 2025-07 | C285: CC500 | D285: General and administrative | E285: 6200 | F285: Facilities and administration | G285: opex | H285: 156880.00
A286: JE000284 | B286: 2025-07 | C286: CC900 | D286: Corporate | E286: 7000 | F286: Depreciation | G286: other | H286: 89268.61
A287: JE000285 | B287: 2025-07 | C287: CC900 | D287: Corporate | E287: 8000 | F287: Interest expense | G287: other | H287: 29687.50
A288: JE000286 | B288: 2025-07 | C288: CC900 | D288: Corporate | E288: 9000 | F288: Income tax | G288: other | H288: 40975.14
A289: JE000287 | B289: 2025-08 | C289: CC900 | D289: Corporate | E289: 4000 | F289: Transaction fees | G289: revenue | H289: -2128226.09
A290: JE000288 | B290: 2025-08 | C290: CC900 | D290: Corporate | E290: 4100 | F290: Subscription fees | G290: revenue | H290: -747000.00
A291: JE000289 | B291: 2025-08 | C291: CC900 | D291: Corporate | E291: 4200 | F291: FX markup | G291: revenue | H291: -231169.39
A292: JE000290 | B292: 2025-08 | C292: CC900 | D292: Corporate | E292: 5000 | F292: Scheme and interchange costs | G292: cogs | H292: 1065887.26 | I292: includes scheme refund for Apr to Jul
A293: JE000291 | B293: 2025-08 | C293: CC900 | D293: Corporate | E293: 5100 | F293: Cloud hosting | G293: cogs | H293: 207296.23 | I293: reclass of July cloud invoice
A294: JE000292 | B294: 2025-08 | C294: CC500 | D294: General and administrative | E294: 6200 | F294: Facilities and administration | G294: opex | H294: -88000.00 | I294: reversal of July error
A295: JE000293 | B295: 2025-08 | C295: CC100 | D295: Engineering | E295: 6000 | F295: Salaries and wages | G295: opex | H295: 590000.00
A296: JE000294 | B296: 2025-08 | C296: CC200 | D296: Sales | E296: 6000 | F296: Salaries and wages | G296: opex | H296: 188000.00
A297: JE000295 | B297: 2025-08 | C297: CC300 | D297: Marketing | E297: 6000 | F297: Salaries and wages | G297: opex | H297: 71200.00
A298: JE000296 | B298: 2025-08 | C298: CC400 | D298: Customer support | E298: 6000 | F298: Salaries and wages | G298: opex | H298: 123200.00
A299: JE000297 | B299: 2025-08 | C299: CC500 | D299: General and administrative | E299: 6000 | F299: Salaries and wages | G299: opex | H299: 118300.00
A300: JE000298 | B300: 2025-08 | C300: CC300 | D300: Marketing | E300: 6100 | F300: Marketing programmes | G300: opex | H300: 180000.00
A301: JE000299 | B301: 2025-08 | C301: CC500 | D301: General and administrative | E301: 6200 | F301: Facilities and administration | G301: opex | H301: 156880.00
A302: JE000300 | B302: 2025-08 | C302: CC900 | D302: Corporate | E302: 7000 | F302: Depreciation | G302: other | H302: 89990.80
A303: JE000301 | B303: 2025-08 | C303: CC900 | D303: Corporate | E303: 8000 | F303: Interest expense | G303: other | H303: 28697.92
...

Sheet budget
A1: month | B1: cost_centre | C1: cost_centre_name | D1: account_code | E1: account_name | F1: budget_amount
A2: 2025-01 | B2: CC900 | C2: Corporate | D2: 4000 | E2: Transaction fees | F2: 1587701
A3: 2025-01 | B3: CC900 | C3: Corporate | D3: 4100 | E3: Subscription fees | F3: 685800
A4: 2025-01 | B4: CC900 | C4: Corporate | D4: 4200 | E4: FX markup | F4: 161331
A5: 2025-01 | B5: CC900 | C5: Corporate | D5: 5000 | E5: Scheme and interchange costs | F5: 845067
A6: 2025-01 | B6: CC900 | C6: Corporate | D6: 5100 | E6: Hosting | F6: 105291
A7: 2025-01 | B7: CC300 | C7: Marketing | D7: 6100 | E7: Marketing programmes | F7: 180000
A8: 2025-01 | B8: CC500 | C8: General and administrative | D8: 6200 | E8: Facilities | F8: 156880
A9: 2025-01 | B9: CC900 | C9: Corporate | D9: 7000 | E9: Depreciation | F9: 84556
A10: 2025-01 | B10: CC900 | C10: Corporate | D10: 8000 | E10: Interest expense | F10: 35625
A11: 2025-01 | B11: CC900 | C11: Corporate | D11: 9000 | E11: Income tax | F11: 12960
A12: 2025-01 | B12: CC100 | C12: Engineering | D12: 6000 | E12: Salaries and wages | F12: 507400
... A193: 2025-12 | B193: CC600 | C193: New product | D193: 6000 | E193: Salaries and wages | F193: 96000

Sheet quality
A1: What is wrong with the export, before any analysis
A3: rows | B3: =COUNTA(actuals!A2:A319) | C3: expected 318
A4: distinct journal ids | B4: =SUMPRODUCT(1/COUNTIF(actuals!A2:A319,actuals!A2:A319)) | C4: expected 317
A5: amounts that are not numbers | B5: =SUMPRODUCT(--NOT(ISNUMBER(actuals!H2:H319))) | C5: expected 2
A6: labels with untrimmed spaces | B6: =SUMPRODUCT(--(TRIM(actuals!F2:F319)<>actuals!F2:F319)) | C6: expected 1
A8: The duplicate is JE000261, 590,000 of engineering payroll in 2025-06. It is excluded from the pack by the SUMIFS below, which counts each journal once, and it has been reported to the accountant.

Sheet map
A1: account_code | B1: pack_line | C1: group
A2: 4000 | B2: Transaction fees | C2: revenue
A3: 4100 | B3: Subscription fees | C3: revenue
A4: 4200 | B4: FX markup | C4: revenue
A5: 5000 | B5: Scheme and interchange | C5: cogs
A6: 5100 | B6: Cloud hosting | C6: cogs
A7: 6000 | B7: Salaries | C7: opex
A8: 6100 | B8: Marketing programmes | C8: opex
A9: 6200 | B9: Facilities and admin | C9: opex
A10: 7000 | B10: Depreciation | C10: below
A11: 8000 | B11: Interest | C11: below
A12: 9000 | B12: Tax | C12: below

Sheet calc
A1: journal_id | B1: month | C1: account_code | D1: value | E1: pack_line | F1: first_time | G1: group
A2: =actuals!A2 | B2: =actuals!B2 | C2: =actuals!E2 | D2: =IF(actuals!G2="revenue",-1,1)*IFERROR(actuals!H2,VALUE(SUBSTITUTE(SUBSTITUTE(SUBSTITUTE(actuals!H2,"(","-"),")",""),",",""))) | E2: =INDEX(map!$B$2:$B$12,MATCH(actuals!E2,map!$A$2:$A$12,0)) | F2: =IF(COUNTIF($A$2:$A2,actuals!A2)=1,1,0) | G2: =INDEX(map!$C$2:$C$12,MATCH(actuals!E2,map!$A$2:$A$12,0))
A3: =actuals!A3 | B3: =actuals!B3 | C3: =actuals!E3 | D3: =IF(actuals!G3="revenue",-1,1)*IFERROR(actuals!H3,VALUE(SUBSTITUTE(SUBSTITUTE(SUBSTITUTE(actuals!H3,"(","-"),")",""),",",""))) | E3: =INDEX(map!$B$2:$B$12,MATCH(actuals!E3,map!$A$2:$A$12,0)) | F3: =IF(COUNTIF($A$2:$A3,actuals!A3)=1,1,0) | G3: =INDEX(map!$C$2:$C$12,MATCH(actuals!E3,map!$A$2:$A$12,0))
A4: =actuals!A4 | B4: =actuals!B4 | C4: =actuals!E4 | D4: =IF(actuals!G4="revenue",-1,1)*IFERROR(actuals!H4,VALUE(SUBSTITUTE(SUBSTITUTE(SUBSTITUTE(actuals!H4,"(","-"),")",""),",",""))) | E4: =INDEX(map!$B$2:$B$12,MATCH(actuals!E4,map!$A$2:$A$12,0)) | F4: =IF(COUNTIF($A$2:$A4,actuals!A4)=1,1,0) | G4: =INDEX(map!$C$2:$C$12,MATCH(actuals!E4,map!$A$2:$A$12,0))
A5: =actuals!A5 | B5: =actuals!B5 | C5: =actuals!E5 | D5: =IF(actuals!G5="revenue",-1,1)*IFERROR(actuals!H5,VALUE(SUBSTITUTE(SUBSTITUTE(SUBSTITUTE(actuals!H5,"(","-"),")",""),",",""))) | E5: =INDEX(map!$B$2:$B$12,MATCH(actuals!E5,map!$A$2:$A$12,0)) | F5: =IF(COUNTIF($A$2:$A5,actuals!A5)=1,1,0) | G5: =INDEX(map!$C$2:$C$12,MATCH(actuals!E5,map!$A$2:$A$12,0))
A6: =actuals!A6 | B6: =actuals!B6 | C6: =actuals!E6 | D6: =IF(actuals!G6="revenue",-1,1)*IFERROR(actuals!H6,VALUE(SUBSTITUTE(SUBSTITUTE(SUBSTITUTE(actuals!H6,"(","-"),")",""),",",""))) | E6: =INDEX(map!$B$2:$B$12,MATCH(actuals!E6,map!$A$2:$A$12,0)) | F6: =IF(COUNTIF($A$2:$A6,actuals!A6)=1,1,0) | G6: =INDEX(map!$C$2:$C$12,MATCH(actuals!E6,map!$A$2:$A$12,0))
A7: =actuals!A7 | B7: =actuals!B7 | C7: =actuals!E7 | D7: =IF(actuals!G7="revenue",-1,1)*IFERROR(actuals!H7,VALUE(SUBSTITUTE(SUBSTITUTE(SUBSTITUTE(actuals!H7,"(","-"),")",""),",",""))) | E7: =INDEX(map!$B$2:$B$12,MATCH(actuals!E7,map!$A$2:$A$12,0)) | F7: =IF(COUNTIF($A$2:$A7,actuals!A7)=1,1,0) | G7: =INDEX(map!$C$2:$C$12,MATCH(actuals!E7,map!$A$2:$A$12,0))
A8: =actuals!A8 | B8: =actuals!B8 | C8: =actuals!E8 | D8: =IF(actuals!G8="revenue",-1,1)*IFERROR(actuals!H8,VALUE(SUBSTITUTE(SUBSTITUTE(SUBSTITUTE(actuals!H8,"(","-"),")",""),",",""))) | E8: =INDEX(map!$B$2:$B$12,MATCH(actuals!E8,map!$A$2:$A$12,0)) | F8: =IF(COUNTIF($A$2:$A8,actuals!A8)=1,1,0) | G8: =INDEX(map!$C$2:$C$12,MATCH(actuals!E8,map!$A$2:$A$12,0))
A9: =actuals!A9 | B9: =actuals!B9 | C9: =actuals!E9 | D9: =IF(actuals!G9="revenue",-1,1)*IFERROR(actuals!H9,VALUE(SUBSTITUTE(SUBSTITUTE(SUBSTITUTE(actuals!H9,"(","-"),")",""),",",""))) | E9: =INDEX(map!$B$2:$B$12,MATCH(actuals!E9,map!$A$2:$A$12,0)) | F9: =IF(COUNTIF($A$2:$A9,actuals!A9)=1,1,0) | G9: =INDEX(map!$C$2:$C$12,MATCH(actuals!E9,map!$A$2:$A$12,0))
A10: =actuals!A10 | B10: =actuals!B10 | C10: =actuals!E10 | D10: =IF(actuals!G10="revenue",-1,1)*IFERROR(actuals!H10,VALUE(SUBSTITUTE(SUBSTITUTE(SUBSTITUTE(actuals!H10,"(","-"),")",""),",",""))) | E10: =INDEX(map!$B$2:$B$12,MATCH(actuals!E10,map!$A$2:$A$12,0)) | F10: =IF(COUNTIF($A$2:$A10,actuals!A10)=1,1,0) | G10: =INDEX(map!$C$2:$C$12,MATCH(actuals!E10,map!$A$2:$A$12,0))
A11: =actuals!A11 | B11: =actuals!B11 | C11: =actuals!E11 | D11: =IF(actuals!G11="revenue",-1,1)*IFERROR(actuals!H11,VALUE(SUBSTITUTE(SUBSTITUTE(SUBSTITUTE(actuals!H11,"(","-"),")",""),",",""))) | E11: =INDEX(map!$B$2:$B$12,MATCH(actuals!E11,map!$A$2:$A$12,0)) | F11: =IF(COUNTIF($A$2:$A11,actuals!A11)=1,1,0) | G11: =INDEX(map!$C$2:$C$12,MATCH(actuals!E11,map!$A$2:$A$12,0))
A12: =actuals!A12 | B12: =actuals!B12 | C12: =actuals!E12 | D12: =IF(actuals!G12="revenue",-1,1)*IFERROR(actuals!H12,VALUE(SUBSTITUTE(SUBSTITUTE(SUBSTITUTE(actuals!H12,"(","-"),")",""),",",""))) | E12: =INDEX(map!$B$2:$B$12,MATCH(actuals!E12,map!$A$2:$A$12,0)) | F12: =IF(COUNTIF($A$2:$A12,actuals!A12)=1,1,0) | G12: =INDEX(map!$C$2:$C$12,MATCH(actuals!E12,map!$A$2:$A$12,0))
A13: =actuals!A13 | B13: =actuals!B13 | C13: =actuals!E13 | D13: =IF(actuals!G13="revenue",-1,1)*IFERROR(actuals!H13,VALUE(SUBSTITUTE(SUBSTITUTE(SUBSTITUTE(actuals!H13,"(","-"),")",""),",",""))) | E13: =INDEX(map!$B$2:$B$12,MATCH(actuals!E13,map!$A$2:$A$12,0)) | F13: =IF(COUNTIF($A$2:$A13,actuals!A13)=1,1,0) | G13: =INDEX(map!$C$2:$C$12,MATCH(actuals!E13,map!$A$2:$A$12,0))
... A319: =actuals!A319 | B319: =actuals!B319 | C319: =actuals!E319 | D319: =IF(actuals!G319="revenue",-1,1)*IFERROR(actuals!H319,VALUE(SUBSTITUTE(SUBSTITUTE(SUBSTITUTE(actuals!H319,"(","-"),")",""),",",""))) | E319: =INDEX(map!$B$2:$B$12,MATCH(actuals!E319,map!$A$2:$A$12,0)) | F319: =IF(COUNTIF($A$2:$A319,actuals!A319)=1,1,0) | G319: =INDEX(map!$C$2:$C$12,MATCH(actuals!E319,map!$A$2:$A$12,0))
